<robot name="diff_drive_robot">
  <!-- Базовый корпус робота -->
  <link name="base_link">
    <visual>
      <geometry>
        <box size="1 2 0.5"/> <!-- Пример размера: куб -->
      </geometry>
      <material name="blue"/>
    </visual>
    <collision>
      <geometry>
        <box size="1 2 0.5"/> <!-- Те же размеры для коллизии -->
      </geometry>
    </collision>
    <inertial>
      <mass value="10.0"/>
      <origin rpy="0 0 0" xyz="0 0 0"/>
      <inertia ixx="0.1" ixy="0.0" ixz="0.0" iyy="0.1" iyz="0.0" izz="0.1"/>
    </inertial>
  </link>

  <!-- Левое колесо -->
  <link name="left_wheel">
    <visual>
      <geometry>
        <cylinder length="0.2" radius="0.3"/> <!-- Пример: цилиндрическое колесо -->
      </geometry>
      <material name="black"/>
    </visual>
    <collision>
      <geometry>
        <cylinder length="0.2" radius="0.3"/>
      </geometry>
    </collision>
    <inertial>
      <mass value="2.0"/>
      <origin rpy="0 0 0" xyz="0 0 0"/>
      <inertia ixx="0.01" ixy="0.0" ixz="0.0" iyy="0.01" iyz="0.0" izz="0.01"/>
    </inertial>
  </link>

  <!-- Правое колесо -->
  <link name="right_wheel">
    <visual>
      <geometry>
        <cylinder length="0.2" radius="0.3"/> <!-- Пример: цилиндрическое колесо -->
      </geometry>
      <material name="black"/>
    </visual>
    <collision>
      <geometry>
        <cylinder length="0.2" radius="0.3"/>
      </geometry>
    </collision>
    <inertial>
      <mass value="2.0"/>
      <origin rpy="0 0 0" xyz="0 0 0"/>
      <inertia ixx="0.01" ixy="0.0" ixz="0.0" iyy="0.01" iyz="0.0" izz="0.01"/>
    </inertial>
  </link>

  <!-- Соединения для колес -->
  <joint name="left_wheel_joint" type="continuous">
    <parent link="base_link"/>
    <child link="left_wheel"/>
    <origin xyz="-0.5 0.6 0" rpy="0 -1.57 0"/> <!-- Пример положения -->
    <axis xyz="0 0 1"/>
  </joint>

  <joint name="right_wheel_joint" type="continuous">
    <parent link="base_link"/>
    <child link="right_wheel"/>
    <origin xyz="0.5 0.6 0" rpy="0 1.57 0"/> <!-- Пример положения -->
    <axis xyz="0 0 1"/>
  </joint>
</robot>
